<?xml version="1.0"?>
<robot  xmlns:xacro="http://www.ros.org/wiki/xacro" name="firefighter" >

<xacro:property name="width" value=".2" />

  <material name="blue">
        <color rgba="0 0 0.8 1"/>
  </material>
  <material name="light_blue">
        <color rgba="0 0 1.0 1"/>
  </material>
  <material name="red">
        <color rgba="0.8 0 0 1"/>
  </material>
  <material name="green">
        <color rgba="0 0.8 0 1"/>
  </material>
  <material name="dark_green">
        <color rgba="0 0.5 0 1"/>
  </material>
  <material name="grey">
        <color rgba="0.75 0.75 0.75 1"/>
  </material>
  <material name="white">
        <color rgba="1.0 1.0 1.0 1"/>
  </material>
  <material name="black">
        <color rgba="0 0 0 1"/>
  </material>

  <!-- * * * Leave or take this plugin off as required * * * -->
  <gazebo>
      <plugin name="gazebo_ros_control" filename="libgazebo_ros_control.so">
      <!--robotNamespace>/firefighter_legrip_pi_pl2</robotNamespace-->
      </plugin>
  </gazebo>
  <!-- Used for fixing robot to Gazebo 'base_link' -->
  <link name="world">
    <origin xyz = "0 0 0.012" rpy = " 0 0 1.57"/>
  </link>
  
  <joint name="vitual_joint" type="fixed">
    <parent link="world"/>
    <child link="base"/>
    <origin xyz="0 0 0" rpy="0 0 0"/>
  </joint>

<!-- scene objects -->
     
    <link name="floor">
      <inertial>
            <origin xyz="0 0 0" rpy="0 0 0"/>
            <mass value="1.5" />
            <inertia ixx="0.025" ixy="0.0" ixz="0.0" iyy="0.025" iyz="0.0" izz="0.0125"/>
      </inertial>
      <collision>
        <origin xyz="0 0 0" rpy="0 0 0"/>
        <geometry>
          <box size="10 10 0.01"/>
        </geometry>
      </collision>
      <visual>
        <origin xyz="0 0 0" rpy="0 0 0"/>
        <geometry>
          <box size="10 10 0.01"/>
        </geometry>
        <material name="grey"/>
      </visual>  
    </link>
    
    <gazebo reference="floor">
        <kp>1000.0</kp>
        <kd>1000.0</kd>
        <mu1>1.0</mu1>
        <mu2>1.0</mu2>
        <!--material>Gazebo/wood</material-->
    </gazebo>
    
    <joint name="world_to_floor" type="fixed">
     <parent link="world"/>
     <child link="floor"/>
     <origin xyz="0 0 0" rpy="0 0 0"/>
    </joint>
    
    <link name="env">
     <inertial>
            <origin xyz = "0 0 0.02 " rpy = "1.5708 0 -1.5708"/>
            <mass value="1.5" />
            <inertia ixx="0.025" ixy="0.0" ixz="0.0" iyy="0.025" iyz="0.0" izz="0.0125"/>
     </inertial>
     <collision>
      <geometry>
        <mesh filename="package://mycobot_description/urdf/mycobot/suit_env.dae" scale="1.15 1.15 1.15"/>
      </geometry>
      <origin xyz = "0 0 0" rpy = "1.5708 0 -1.5708"/>
     </collision>
     <visual>
      <geometry>
        <mesh filename="package://mycobot_description/urdf/mycobot/suit_env.dae" scale="1.15 1.15 1.15"/> 
      </geometry>
      <material name="dark_green"/>
      <origin xyz = "0 0 0" rpy = "1.5708 0 -1.5708"/>
     </visual>
    </link>
    
    <gazebo reference="env">
        <kp>1000.0</kp>
        <kd>1000.0</kd>
        <mu1>1.0</mu1>
        <mu2>1.0</mu2>
        <material>Gazebo/White</material>
    </gazebo>
    
    <joint name="world_env" type="fixed">
     <parent link="world"/>
     <child link="env"/>
     <origin xyz="0 0 0" rpy="0 0 0"/>
    </joint>
    
    <joint name="aruco1_joint" type="fixed">
    <axis xyz="0 0 1" />
    <origin xyz="0.12 0.064 0.01" rpy="0 0 3.14"/>
    <parent link="world"/>
    <child link="aruco1"/>
  </joint>

  <link name="aruco1">
    <collision>
      <origin xyz="0 0 0" rpy="0 0 0"/>
      <geometry>
    <box size="0.03 0.03 0.0001"/>
      </geometry>
    </collision>

    <visual>
      <origin xyz="0 0 0" rpy="0 0 0"/>
      <geometry>
    <box size="0.03 0.03 0.0001"/>
      </geometry>
      <material name="light_blue"/>
    </visual>

    <inertial>
      <mass value="1e-5" />
      <origin xyz="0 0 0" rpy="0 0 0"/>
      <inertia ixx="1e-6" ixy="0" ixz="0" iyy="1e-6" iyz="0" izz="1e-6" />
    </inertial>
  </link>
  
  <gazebo reference="aruco1">
        <material>Gazebo/aruco1</material>
  </gazebo>
  
  <joint name="aruco2_joint" type="fixed">
    <axis xyz="0 0 1" />
    <origin xyz="0.249 -0.064 0.01" rpy="0 0 3.14"/>
    <parent link="world"/>
    <child link="aruco2"/>
  </joint>

  <link name="aruco2">
    <collision>
      <origin xyz="0 0 0" rpy="0 0 0"/>
      <geometry>
    <box size="0.03 0.03 0.0001"/>
      </geometry>
    </collision>

    <visual>
      <origin xyz="0 0 0" rpy="0 0 0"/>
      <geometry>
    <box size="0.03 0.03 0.0001"/>
      </geometry>
      <material name="light_blue"/>
    </visual>

    <inertial>
      <mass value="1e-5" />
      <origin xyz="0 0 0" rpy="0 0 0"/>
      <inertia ixx="1e-6" ixy="0" ixz="0" iyy="1e-6" iyz="0" izz="1e-6" />
    </inertial>
  </link>
  
  <gazebo reference="aruco2">
        <material>Gazebo/aruco2</material>
  </gazebo>
    
    <!--link name="container">
    <inertial>
          <origin xyz="0 0.3 0" rpy="0 0 0"/>
          <mass value="1" />
          <inertia ixx="0.025" ixy="0.0" ixz="0.0" iyy="0.025" iyz="0.0" izz="0.0125"/>
    </inertial>
    <visual>
      <geometry>
       <mesh filename="package://mycobot_description/urdf/320_urdf/Practica_recoger_dejar_c3.dae" scale="2 2 2"/>
      </geometry>
      <origin xyz="0 0.3 0" rpy="0 0 0"/>
    </visual>
    <collision>
      <geometry>
        <mesh filename="package://mycobot_description/urdf/320_urdf/Practica_recoger_dejar_c3.dae" scale="2 2 2"/>
      </geometry>
      <origin xyz="0 0.3 0" rpy="0 0 0"/>
    </collision>
  </link>

  <gazebo reference="container">
        <kp>5000.0</kp>
        <kd>5000.0</kd>
        <mu1>1.0</mu1>
        <mu2>1.0</mu2>
        <material>Gazebo/Green</material>
  </gazebo>
  
  <joint name="floor_to_container" type="fixed">
     <parent link="world"/>
     <child link="container"/>
     <origin xyz="0 0 0" rpy="0 0 0"/>
    </joint-->
    
  

<!--Robot-->

  <link name="base">
    <inertial>
          <origin xyz = "0 0 0 " rpy = " 0 0 0"/>
          <mass value="1" />
          <inertia ixx="0.025" ixy="0.0" ixz="0.0" iyy="0.025" iyz="0.0" izz="0.0125"/>
    </inertial>
    <visual>
      <geometry>
       <mesh filename="package://mycobot_description/urdf/320_urdf/base.dae"/>
       <!--mesh filename="file:///home/stefanos/catkin_ws/src/myCobotROS/mycobot_description/urdf/320_urdf/base.dae"/-->
       <!--cylinder length="0.102" radius="0.0725"/-->
      </geometry>
      <origin xyz = "0 0 0 " rpy = " 0 0 0"/>
      <!--origin xyz = "0 0 0.05 " rpy = " 0 0 0"/-->
    </visual>
    <collision>
      <geometry>
        <cylinder length="0.102" radius="0.0725"/>
      </geometry>
      <origin xyz = "0 0 0.05 " rpy = " 0 0 0"/>
    </collision>
  </link>

  <gazebo reference="base">
        <kp>1000.0</kp>
        <kd>1000.0</kd>
        <mu1>1.0</mu1>
        <mu2>1.0</mu2>
        <material>Gazebo/Grey</material>
  </gazebo>

  <link name="link1">
    <inertial>
            <origin xyz = "0 0 0 " rpy = " 0 0 0"/>
            <mass value="0.5" />
            <inertia ixx="0.005" ixy="0.0" ixz="0.0" iyy="0.005" iyz="0.0" izz="0.005"/>
    </inertial>
    <visual>
      <geometry>
       <mesh filename="package://mycobot_description/urdf/320_urdf/link1.dae"/>
       <!--cylinder length="0.106" radius="0.043"/-->
      </geometry>
      <origin xyz = "0 0 0 " rpy = " 0 0 0"/>
      <!--origin xyz = "0 0 -0.02 " rpy = " 0 0 0"/-->
    </visual>
    <collision>
      <geometry>
        <cylinder length="0.106" radius="0.043"/>
      </geometry>
      <origin xyz = "0 0 -0.02 " rpy = " 0 0 0"/>
    </collision>
  </link>

  <gazebo reference="link1">
        <kp>1000.0</kp>
        <kd>1000.0</kd>
        <mu1>1.0</mu1>
        <mu2>1.0</mu2>
        <material>Gazebo/White</material>
  </gazebo>

  <link name="link2">
    <inertial>
            <origin xyz = "0.0 0 0.0587 " rpy = " 0 0 3.1415926"/>
            <mass value="0.4" />
            <inertia ixx="0.003" ixy="0.0" ixz="0.0" iyy="0.003" iyz="0.0" izz="0.003"/>
    </inertial>
    <visual>
      <geometry>
       <mesh filename="package://mycobot_description/urdf/320_urdf/link2.dae"/>
       <!--cylinder length="0.18" radius="0.036"/-->
      </geometry>
      <origin xyz = "0 0 0.0587 " rpy = " 0 0 3.1415926"/>
      <!--origin xyz = "0.07 0 0.095 " rpy = " 0 -1.5708 0"/-->
    </visual>
    <collision>
      <geometry>
        <cylinder length="0.18" radius="0.036"/>
      </geometry>
      <origin xyz = "0.07 0 0.095 " rpy = " 0 -1.5708 0"/>
    </collision>
  </link>

  <gazebo reference="link2">
        <kp>1000.0</kp>
        <kd>1000.0</kd>
        <mu1>1.0</mu1>
        <mu2>1.0</mu2>
        <material>Gazebo/White</material>
  </gazebo>

  <link name="link3">
    <inertial>
            <origin xyz = "0.0 0 0.038 " rpy = " 0 0 3.1415926"/>
            <mass value="0.4" />
            <inertia ixx="0.003" ixy="0.0" ixz="0.0" iyy="0.003" iyz="0.0" izz="0.003"/>
    </inertial>
    <visual>
      <geometry>
       <mesh filename="package://mycobot_description/urdf/320_urdf/link3.dae"/>
       <!--cylinder length="0.14" radius="0.0305"/-->
      </geometry>
      <origin xyz = "0 0 0.038 " rpy = " 0 0 3.1415926"/>
      <!--origin xyz = "0.044 0 0 " rpy = " 0 -1.5708 0"/-->
    </visual>
    <collision>
      <geometry>
        <cylinder length="0.14" radius="0.0305"/>
      </geometry>
      <origin xyz = "0.044 0 0 " rpy = " 0 -1.5708 0"/>
    </collision>
  </link>

  <gazebo reference="link3">
        <kp>1000.0</kp>
        <kd>1000.0</kd>
        <mu1>1.0</mu1>
        <mu2>1.0</mu2>
        <material>Gazebo/White</material>
  </gazebo>

  <link name="link4">
    <inertial>
            <origin xyz = "0 -0.001 0 " rpy = " 0 0 0"/>
            <mass value="0.3" />
            <inertia ixx="0.003" ixy="0.0" ixz="0.0" iyy="0.003" iyz="0.0" izz="0.003"/>
    </inertial>
    <visual>
      <geometry>
       <mesh filename="package://mycobot_description/urdf/320_urdf/link4.dae"/>
       <!--cylinder length="0.083" radius="0.029"/-->
      </geometry>
      <origin xyz = "0 -0.001 0 " rpy = " 0 0 0"/>
      <!--origin xyz = "0.0 -0.014 0 " rpy = " 0 -1.5708 1.5708"/-->
    </visual>
    <collision>
      <geometry>
        <cylinder length="0.083" radius="0.029"/>
      </geometry>
      <origin xyz = "0.0 -0.014 0 " rpy = " 0 -1.5708 1.5708"/>
    </collision>
  </link>

  <gazebo reference="link4">
        <kp>1000.0</kp>
        <kd>1000.0</kd>
        <mu1>1.0</mu1>
        <mu2>1.0</mu2>
        <material>Gazebo/White</material>
  </gazebo>

  <link name="link5">
    <inertial>
            <origin xyz = "0 0.002 0 " rpy = " 0 0 3.1415926"/>
            <mass value="0.1" />
            <inertia ixx="0.002835" ixy="0.0" ixz="0.0" iyy="0.002835" iyz="0.0" izz="0.00324"/>
    </inertial>
    <visual>
      <geometry>
       <mesh filename="package://mycobot_description/urdf/320_urdf/link5.dae"/>
      </geometry>
      <origin xyz = "0 0.002  0 " rpy = " 0  0 3.1415926"/>
      <!--origin xyz = "0 -0.01 0 " rpy = " 1.5708 1.5708 0"/-->
    </visual>
    <visual>
      <geometry>
       <cylinder length="0.002" radius="0.026"/>
      </geometry>
      <origin xyz = "0 0.039  0 " rpy = " 1.57  0 3.1415926"/>
      <material name = "grey">
        <color rgba = "0.5 0.5 0.5 1"/>
      </material>
    </visual>
    <collision>
      <geometry>
        <cylinder length="0.0849" radius="0.029"/>
      </geometry>
      <origin xyz = "0 -0.01 0 " rpy = " 1.5708 1.5708 0"/>
    </collision>
  </link>

  <gazebo reference="link5">
        <kp>1000.0</kp>
        <kd>1000.0</kd>
        <mu1>1.0</mu1>
        <mu2>1.0</mu2>
        <material>Gazebo/White</material>
  </gazebo>

  <link name="link6">
    <inertial>
            <origin xyz = "0 0 -0.01 " rpy = " 0 0 0"/>
            <mass value="0.1" />
            <inertia ixx="0.002835" ixy="0.0" ixz="0.0" iyy="0.002835" iyz="0.0" izz="0.00324"/>
    </inertial>
    <visual>
      <geometry>
        <cylinder length="0.02" radius="0.026"/>
      </geometry>
      <material name = "grey">
        <color rgba = "0.5 0.5 0.5 1"/>
      </material>
    <origin xyz = "0 0 -0.01 " rpy = " 0 0 0"/>
    </visual>
    <collision>
      <geometry>
        <cylinder length="0.0225" radius="0.026"/>
      </geometry>
      <origin xyz = "0.0 0 -0.01 " rpy = " 0 0 0"/>
    </collision>
  </link>

  <gazebo reference="link6">
        <kp>1000.0</kp>
        <kd>1000.0</kd>
        <mu1>1.0</mu1>
        <mu2>1.0</mu2>
        <material>Gazebo/Grey</material>
  </gazebo>

  <link name="link7">
    <inertial>
            <origin xyz = "0 0.0265 0 " rpy = " 1.57 0 3.1415926"/>
            <mass value="0.1" />
            <inertia ixx="0.002835" ixy="0.0" ixz="0.0" iyy="0.002835" iyz="0.0" izz="0.00324"/>
    </inertial>
    
    
    <visual>
      <geometry>
       <box size="0.028 0.028 0.028"/>
      </geometry>
      <origin xyz = "0 0.0265  0 " rpy = " 1.57  0 3.1415926"/>
      <material name = "green">
        <color rgba="0 0.8 0 1"/>
      </material>
    </visual>
    <collision>
      <geometry>
        <box size="0.028 0.028 0.028"/>
      </geometry>
      <origin xyz = "0 0.0265  0 " rpy = " 1.57  0 3.1415926"/>
    </collision>
  </link>

  <gazebo reference="link7">
        <kp>1000.0</kp>
        <kd>1000.0</kd>
        <mu1>1.0</mu1>
        <mu2>1.0</mu2>
        <material>Gazebo/Green</material>
  </gazebo>  

  
  
  <joint name="joint2_to_joint1" type="revolute">
    <axis xyz="0 0 1"/>
    <limit effort = "1000.0" lower = "-3.14" upper = "3.14159" velocity = "1.0"/>
    <parent link="base"/>
    <child link="link1"/>
    <origin xyz= "0 0 0.17846" rpy = "0 0 0"/>
    <dynamics damping="2.0" friction="1.0"/>
  </joint>

  <transmission name="tran1">
        <type>transmission_interface/SimpleTransmission</type>
        <joint name="joint2_to_joint1">
            <hardwareInterface>hardware_interface/EffortJointInterface</hardwareInterface>    
        </joint>
        <actuator name="motor1">
            <hardwareInterface>hardware_interface/EffortJointInterface</hardwareInterface>
            <mechanicalReduction>1</mechanicalReduction>
        </actuator>
  </transmission>

  <joint name="joint3_to_joint2" type="revolute">
    <axis xyz="0 0 1"/>
    <limit effort = "1000.0" lower = "-3.14" upper = "3.14159" velocity = "0.4"/>
    <parent link="link1"/>
    <child link="link2"/>
    <origin xyz= "0 0 0" rpy = "0 -1.57080 1.57080"/>
    <dynamics damping="2.0" friction="1.0"/>
  </joint>

  <transmission name="tran2">
        <type>transmission_interface/SimpleTransmission</type>
        <joint name="joint3_to_joint2">
            <hardwareInterface>hardware_interface/EffortJointInterface</hardwareInterface>
        </joint>
        <actuator name="motor2">
            <hardwareInterface>hardware_interface/EffortJointInterface</hardwareInterface>
            <mechanicalReduction>1</mechanicalReduction>
        </actuator>
  </transmission>

  <joint name="joint4_to_joint3" type="revolute">
    <axis xyz=" 0 0 1"/>
    <limit effort = "1000.0" lower = "-3.14" upper = "3.14159" velocity = "0.4"/>
    <parent link="link2"/>
    <child link="link3"/>
    <origin xyz= "0.13635 0 0   " rpy = "0 0 0"/>
    <dynamics damping="2.0" friction="1.0"/>
  </joint>

  <transmission name="tran3">
        <type>transmission_interface/SimpleTransmission</type>
        <joint name="joint4_to_joint3">
            <hardwareInterface>hardware_interface/EffortJointInterface</hardwareInterface>
        </joint>
        <actuator name="motor3">
            <hardwareInterface>hardware_interface/EffortJointInterface</hardwareInterface>
            <mechanicalReduction>1</mechanicalReduction>
        </actuator>
  </transmission>

  <joint name="joint5_to_joint4" type="revolute">
    <axis xyz=" 0 0 1"/>
    <limit effort = "1000.0" lower = "-3.14" upper = "3.14159" velocity = "1.0"/>
    <parent link="link3"/>
    <child link="link4"/>
    <origin xyz= "0.1 0  0.090" rpy = "0 0 1.57080"/>
    <dynamics damping="2.0" friction="1.0"/>
  </joint>

  <transmission name="tran4">
        <type>transmission_interface/SimpleTransmission</type>
        <joint name="joint5_to_joint4">
            <hardwareInterface>hardware_interface/EffortJointInterface</hardwareInterface>
        </joint>
        <actuator name="motor4">
            <hardwareInterface>hardware_interface/EffortJointInterface</hardwareInterface>
            <mechanicalReduction>1</mechanicalReduction>
        </actuator>
  </transmission>

  <joint name="joint6_to_joint5" type="revolute">
    <axis xyz="0 0 1"/>
    <limit effort = "1000.0" lower = "-3.14" upper = "3.14159" velocity = "1.0"/>
    <parent link="link4"/>
    <child link="link5"/>
    <origin xyz= "0 -0.0847 0" rpy = "1.57080 1.57080 0"/>
    <dynamics damping="2.0" friction="1.0"/>
  </joint>

  <transmission name="tran5">
        <type>transmission_interface/SimpleTransmission</type>
        <joint name="joint6_to_joint5">
            <hardwareInterface>hardware_interface/EffortJointInterface</hardwareInterface>
        </joint>
        <actuator name="motor5">
            <hardwareInterface>hardware_interface/EffortJointInterface</hardwareInterface>
            <mechanicalReduction>1</mechanicalReduction>
        </actuator>
  </transmission>

  <joint name="joint6output_to_joint6" type="revolute">
    <axis xyz="0 0 1"/>
    <limit effort = "1000.0" lower = "-3.14" upper = "3.14159" velocity = "1.0"/>
    <parent link="link5"/>
    <child link="link6"/>
    <origin xyz= "0 -0.06 0" rpy = "-1.57080 3.14 0 "/>
    <dynamics damping="2.0" friction="1.0"/>
  </joint>

  <transmission name="tran6">
        <type>transmission_interface/SimpleTransmission</type>
        <joint name="joint6output_to_joint6">
            <hardwareInterface>hardware_interface/EffortJointInterface</hardwareInterface>
        </joint>
        <actuator name="motor6">
            <hardwareInterface>hardware_interface/EffortJointInterface</hardwareInterface>
            <mechanicalReduction>1</mechanicalReduction>
        </actuator>
  </transmission>

  <joint name="joint7_to_joint5" type="fixed">
    <parent link="link5"/>
    <child link="link7"/>
    <origin xyz= "-0.0265 0.028 0" rpy = "1.57080 1.57080 0"/>
  </joint>
  
  <joint name="gripper_to_joint6output" type="fixed">
    <axis xyz="0 0 0"/>
    <parent link="link6"/>
    <child link="sucker"/>
    <origin xyz= "0 0 0" rpy = "0 0 0 "/>
  </joint> 
  
  
  
  <link name="tool_center_point" />
  <joint name="tool_center_point_joint" type="fixed">
    <parent link="sucker"/>
    <child link = "tool_center_point" />
    <origin xyz="0.0 0.0 0.105" rpy="0.0 0.0 0.0" />
  </joint>
  
  <!-- Suction Gripper -->
  <link name="sucker">
      <gravity>0</gravity>
      <visual>
        
        <origin rpy="0 0 0" xyz="0 0 0"/>
        <geometry>
          <cylinder length="0.01" radius="0.005"/>
        </geometry>
        <material name="transparent">
          <color rgba="0 0 0 0"/>
        </material>
      </visual>
      <inertial>
        <origin rpy="0 0 0" xyz="0.000000 0.000000 0.000000"/>
        <mass value="0.0001"/>
        <inertia ixx="1e-08" ixy="0" ixz="0" iyy="1e-08" iyz="0" izz="1e-08"/>
      </inertial>
  </link>
  
  <gazebo reference="sucker">
        <material>Gazebo/BlueTransparent</material>
        
  </gazebo>
  
  <joint name="sucker_joint" type="revolute">
      <parent link="link6" />
      <child link="sucker" />
      <origin rpy="0 0 0" xyz="0 0 -0.04" />
      <limit effort="100" velocity="1.0" lower="0" upper="0" />
  </joint>
  
  <link name="sucker_visual">
      
      <collision>
        <origin rpy="0 0 0" xyz="0 0 0"/>
        <geometry>
          <mesh filename="package://mycobot_description/urdf/320_urdf/suction_gripper_320_body.dae"/>
        </geometry>
        <material name="blue">
          <color rgba="0 0 0.8 1"/>
        </material>
      </collision>
      <visual>
        <origin rpy="0 0 0" xyz="0 0 0"/>
        <geometry>
          <mesh filename="package://mycobot_description/urdf/320_urdf/suction_gripper_320_body.dae"/>
        </geometry>
        <material name="blue">
          <color rgba="0 0 0.8 1"/>
        </material>
      </visual>
      <inertial>
        <origin rpy="0 0 0" xyz="0.000000 0.000000 0.000000"/>
        <mass value="0.01"/>
        <inertia ixx="1e-05" ixy="0" ixz="0" iyy="1e-05" iyz="0" izz="1e-05"/>
      </inertial>
  </link>
  
  <joint name="sucker_joint_visual" type="fixed">
      <axis xyz="0 0 1"/>
      <parent link="link6" />
      <child link="sucker_visual" />
      <origin rpy="0 0 0" xyz="0 0 -0.04" />
      <dynamics damping="2.0" friction="1.0"/>
  </joint>
 
  <!--transmission name="tran7">
        <type>transmission_interface/SimpleTransmission</type>
        <joint name="sucker_joint">
            <hardwareInterface>hardware_interface/EffortJointInterface</hardwareInterface>
        </joint>
        <actuator name="motor7">
            <hardwareInterface>hardware_interface/EffortJointInterface</hardwareInterface>
            <mechanicalReduction>1</mechanicalReduction>
        </actuator>
  </transmission-->
  
  <gazebo>
      <plugin name="gazebo_ros_vacuum_gripper" filename="libgazebo_ros_vacuum_gripper.so">
        <robotNamespace>/</robotNamespace>
        <bodyName>sucker</bodyName>
        <bodyName>sucker2</bodyName>
        <topicName>grasping</topicName>
        <maxForce>500</maxForce>
      </plugin>
  </gazebo>

  <!-- Camera Vision -->
  <joint name="camera_joint" type="fixed">
    <axis xyz="0 0 1" />
    <origin xyz="0.27 -0.005 0.335" rpy="0 1.57 3.14"/>
    <parent link="world"/>
    <child link="camera_link"/>
  </joint>

  <link name="camera_link">
    <collision>
      <origin xyz="0 0 0" rpy="0 0 0"/>
      <geometry>
    <box size="0.02 0.02 0.02"/>
      </geometry>
    </collision>

    <visual>
      <origin xyz="0 0 0" rpy="0 0 0"/>
      <geometry>
    <box size="0.02 0.02 0.01"/>
      </geometry>
      <material name="red"/>
    </visual>

    <inertial>
      <mass value="1e-5" />
      <origin xyz="0 0 0" rpy="0 0 0"/>
      <inertia ixx="1e-6" ixy="0" ixz="0" iyy="1e-6" iyz="0" izz="1e-6" />
    </inertial>
  </link>
  
  <gazebo reference="camera_link">
        <material>Gazebo/Red</material>
  </gazebo>

  <!-- Camera Vision Plugin Properties-->
  <gazebo reference="camera_link">
    <sensor type="camera" name="camera1">
      <update_rate>30.0</update_rate>
      <camera name="head">
        <horizontal_fov>1</horizontal_fov>
        <image>
          <width>400</width>
          <height>400</height>
          <format>R8G8B8</format>
        </image>
        <clip>
          <near>0.02</near>
          <far>300</far>
        </clip>
        <noise>
          <type>gaussian</type>
          <!-- Noise is sampled independently per pixel on each frame.
               That pixel's noise value is added to each of its color
               channels, which at that point lie in the range [0,1]. -->
          <mean>0.0</mean>
          <stddev>0.007</stddev>
        </noise>
      </camera>
      <plugin name="camera_controller" filename="libgazebo_ros_camera.so">
        <alwaysOn>true</alwaysOn>
        <updateRate>0.0</updateRate>
        <cameraName>/camera1</cameraName>
        <imageTopicName>image_raw</imageTopicName>
        <cameraInfoTopicName>camera_info</cameraInfoTopicName>
        <frameName>camera_link</frameName>
        <hackBaseline>0.07</hackBaseline>
        <distortionK1>0.0</distortionK1>
        <distortionK2>0.0</distortionK2>
        <distortionK3>0.0</distortionK3>
        <distortionT1>0.0</distortionT1>
        <distortionT2>0.0</distortionT2>
      </plugin>
    </sensor>
  </gazebo>

  

</robot>
